Traceback (most recent call last):
  File "/home/jubayer/anaconda3/envs/book-template/lib/python3.7/site-packages/jupyter_cache/executors/basic.py", line 157, in execute
    executenb(nb_bundle.nb, cwd=tmpdirname)
  File "/home/jubayer/.local/lib/python3.7/site-packages/nbconvert/preprocessors/execute.py", line 737, in executenb
    return ep.preprocess(nb, resources, km=km)[0]
  File "/home/jubayer/.local/lib/python3.7/site-packages/nbconvert/preprocessors/execute.py", line 405, in preprocess
    nb, resources = super(ExecutePreprocessor, self).preprocess(nb, resources)
  File "/home/jubayer/.local/lib/python3.7/site-packages/nbconvert/preprocessors/base.py", line 69, in preprocess
    nb.cells[index], resources = self.preprocess_cell(cell, resources, index)
  File "/home/jubayer/.local/lib/python3.7/site-packages/nbconvert/preprocessors/execute.py", line 448, in preprocess_cell
    raise CellExecutionError.from_cell_and_msg(cell, out)
nbconvert.preprocessors.execute.CellExecutionError: An error occurred while executing the following cell:
------------------
# Read the DNA sequence file 
f = open(inputfile, "r")
seq = f.read()
------------------

[0;31m---------------------------------------------------------------------------[0m
[0;31mFileNotFoundError[0m                         Traceback (most recent call last)
[0;32m<ipython-input-2-1cf75f8521eb>[0m in [0;36m<module>[0;34m[0m
[1;32m      1[0m [0;31m# Read the DNA sequence file[0m[0;34m[0m[0;34m[0m[0;34m[0m[0m
[0;32m----> 2[0;31m [0mf[0m [0;34m=[0m [0mopen[0m[0;34m([0m[0minputfile[0m[0;34m,[0m [0;34m"r"[0m[0;34m)[0m[0;34m[0m[0;34m[0m[0m
[0m[1;32m      3[0m [0mseq[0m [0;34m=[0m [0mf[0m[0;34m.[0m[0mread[0m[0;34m([0m[0;34m)[0m[0;34m[0m[0;34m[0m[0m

[0;31mFileNotFoundError[0m: [Errno 2] No such file or directory: '../data/dna.txt'
FileNotFoundError: [Errno 2] No such file or directory: '../data/dna.txt'

