Traceback (most recent call last):
  File "/home/jubayer/anaconda3/envs/book-template/lib/python3.7/site-packages/jupyter_cache/executors/basic.py", line 157, in execute
    executenb(nb_bundle.nb, cwd=tmpdirname)
  File "/home/jubayer/.local/lib/python3.7/site-packages/nbconvert/preprocessors/execute.py", line 737, in executenb
    return ep.preprocess(nb, resources, km=km)[0]
  File "/home/jubayer/.local/lib/python3.7/site-packages/nbconvert/preprocessors/execute.py", line 405, in preprocess
    nb, resources = super(ExecutePreprocessor, self).preprocess(nb, resources)
  File "/home/jubayer/.local/lib/python3.7/site-packages/nbconvert/preprocessors/base.py", line 69, in preprocess
    nb.cells[index], resources = self.preprocess_cell(cell, resources, index)
  File "/home/jubayer/.local/lib/python3.7/site-packages/nbconvert/preprocessors/execute.py", line 448, in preprocess_cell
    raise CellExecutionError.from_cell_and_msg(cell, out)
nbconvert.preprocessors.execute.CellExecutionError: An error occurred while executing the following cell:
------------------
# Read sequence(MSA)
seq = AlignIO.read("../data/msa.phy", "phylip")
print(seq)
------------------

[0;31m---------------------------------------------------------------------------[0m
[0;31mFileNotFoundError[0m                         Traceback (most recent call last)
[0;32m<ipython-input-2-42223fcb8537>[0m in [0;36m<module>[0;34m[0m
[1;32m      1[0m [0;31m# Read sequence(MSA)[0m[0;34m[0m[0;34m[0m[0;34m[0m[0m
[0;32m----> 2[0;31m [0mseq[0m [0;34m=[0m [0mAlignIO[0m[0;34m.[0m[0mread[0m[0;34m([0m[0;34m"../data/msa.phy"[0m[0;34m,[0m [0;34m"phylip"[0m[0;34m)[0m[0;34m[0m[0;34m[0m[0m
[0m[1;32m      3[0m [0mprint[0m[0;34m([0m[0mseq[0m[0;34m)[0m[0;34m[0m[0;34m[0m[0m

[0;32m~/anaconda3/envs/book-template/lib/python3.7/site-packages/Bio/AlignIO/__init__.py[0m in [0;36mread[0;34m(handle, format, seq_count, alphabet)[0m
[1;32m    438[0m     [0miterator[0m [0;34m=[0m [0mparse[0m[0;34m([0m[0mhandle[0m[0;34m,[0m [0mformat[0m[0;34m,[0m [0mseq_count[0m[0;34m,[0m [0malphabet[0m[0;34m)[0m[0;34m[0m[0;34m[0m[0m
[1;32m    439[0m     [0;32mtry[0m[0;34m:[0m[0;34m[0m[0;34m[0m[0m
[0;32m--> 440[0;31m         [0malignment[0m [0;34m=[0m [0mnext[0m[0;34m([0m[0miterator[0m[0;34m)[0m[0;34m[0m[0;34m[0m[0m
[0m[1;32m    441[0m     [0;32mexcept[0m [0mStopIteration[0m[0;34m:[0m[0;34m[0m[0;34m[0m[0m
[1;32m    442[0m         [0;32mraise[0m [0mValueError[0m[0;34m([0m[0;34m"No records found in handle"[0m[0;34m)[0m [0;32mfrom[0m [0;32mNone[0m[0;34m[0m[0;34m[0m[0m

[0;32m~/anaconda3/envs/book-template/lib/python3.7/site-packages/Bio/AlignIO/__init__.py[0m in [0;36mparse[0;34m(handle, format, seq_count, alphabet)[0m
[1;32m    364[0m         [0;32mraise[0m [0mTypeError[0m[0;34m([0m[0;34m"Need integer for seq_count (sequences per alignment)"[0m[0;34m)[0m[0;34m[0m[0;34m[0m[0m
[1;32m    365[0m [0;34m[0m[0m
[0;32m--> 366[0;31m     [0;32mwith[0m [0mas_handle[0m[0;34m([0m[0mhandle[0m[0;34m)[0m [0;32mas[0m [0mfp[0m[0;34m:[0m[0;34m[0m[0;34m[0m[0m
[0m[1;32m    367[0m         [0;31m# Map the file format to a sequence iterator:[0m[0;34m[0m[0;34m[0m[0;34m[0m[0m
[1;32m    368[0m         [0;32mif[0m [0mformat[0m [0;32min[0m [0m_FormatToIterator[0m[0;34m:[0m[0;34m[0m[0;34m[0m[0m

[0;32m~/anaconda3/envs/book-template/lib/python3.7/contextlib.py[0m in [0;36m__enter__[0;34m(self)[0m
[1;32m    110[0m         [0;32mdel[0m [0mself[0m[0;34m.[0m[0margs[0m[0;34m,[0m [0mself[0m[0;34m.[0m[0mkwds[0m[0;34m,[0m [0mself[0m[0;34m.[0m[0mfunc[0m[0;34m[0m[0;34m[0m[0m
[1;32m    111[0m         [0;32mtry[0m[0;34m:[0m[0;34m[0m[0;34m[0m[0m
[0;32m--> 112[0;31m             [0;32mreturn[0m [0mnext[0m[0;34m([0m[0mself[0m[0;34m.[0m[0mgen[0m[0;34m)[0m[0;34m[0m[0;34m[0m[0m
[0m[1;32m    113[0m         [0;32mexcept[0m [0mStopIteration[0m[0;34m:[0m[0;34m[0m[0;34m[0m[0m
[1;32m    114[0m             [0;32mraise[0m [0mRuntimeError[0m[0;34m([0m[0;34m"generator didn't yield"[0m[0;34m)[0m [0;32mfrom[0m [0;32mNone[0m[0;34m[0m[0;34m[0m[0m

[0;32m~/anaconda3/envs/book-template/lib/python3.7/site-packages/Bio/File.py[0m in [0;36mas_handle[0;34m(handleish, mode, **kwargs)[0m
[1;32m     69[0m     """
[1;32m     70[0m     [0;32mtry[0m[0;34m:[0m[0;34m[0m[0;34m[0m[0m
[0;32m---> 71[0;31m         [0;32mwith[0m [0mopen[0m[0;34m([0m[0mhandleish[0m[0;34m,[0m [0mmode[0m[0;34m,[0m [0;34m**[0m[0mkwargs[0m[0;34m)[0m [0;32mas[0m [0mfp[0m[0;34m:[0m[0;34m[0m[0;34m[0m[0m
[0m[1;32m     72[0m             [0;32myield[0m [0mfp[0m[0;34m[0m[0;34m[0m[0m
[1;32m     73[0m     [0;32mexcept[0m [0mTypeError[0m[0;34m:[0m[0;34m[0m[0;34m[0m[0m

[0;31mFileNotFoundError[0m: [Errno 2] No such file or directory: '../data/msa.phy'
FileNotFoundError: [Errno 2] No such file or directory: '../data/msa.phy'

